Workbook

Sheet Consolidated
A1: MM, WM + SRM | B1: Grade | C1: Exp Level | D1: JD Ref ID | E1: JD | F1: Panel
A2: SAP SD, LE | B2: IS1 | C2: =_xlfn.IFNA(VLOOKUP(B2,Metadata!$G$1:$H$8,2,),"-") -> 0-2 yrs | D2: =_xlfn.CONCAT(A2,"_",B2) -> SAP SD, LE_IS1 | E2: Good communication and interpersonal skills. Should be able to learn quickly on the new areas / cross functional areas Experience either worked in the SAP AMS / SAP config and development track Experince in SAP SD mainly covering Understanding on Sales Process, Contract management, Pricing concepts, OTC, Partner Determination, Text Management, Pricing, Taxes, Billing, Credit Management, Back Orders, and Master Data Management (MDM). Experience in configuring Master Data, Document Types (Sales Order Types, Delivery Documents, Billing Documents, Credit and debit memo, etc.) including special order types (Third Party Processing, Consignment Processing, Inter-Company Billing and Inter-company stock transfers), Availability Check, Material Listing/Exclusion, Rebate processing, Deliveries and Post Goods Issues. Experience Required : 0-2 years of experience with 1 implementation on SAP ERP implementation experience and 1 AMS experience worked with global customers Good understanding of SAP Fiori apps Experience in SAP cross-functional areas such as FI/CO, MM/PP Good understanding of all types of order processing models, including B2B, B2C, EDI would be added advantage Experience in project cut-over, successful go-live and client handling during PGLS and alignment with AMS teams will be valued. Good knowledge in the below areas : Electronic data interchange (EDI) : EDI Mapping Integration: Materials Management(MM), Finance, Transportation Management, Management Accounting Experience of third-party application integration using SAP PI/PO such as WM etc.
A3: SAP SD, LE | B3: IS2 | C3: =_xlfn.IFNA(VLOOKUP(B3,Metadata!$G$1:$H$8,2,),"-") -> 2-5 yrs | D3: =_xlfn.CONCAT(A3,"_",B3) -> SAP SD, LE_IS2 | E3: Good communication and interpersonal skills. Should be able to learn quickly on the new areas / cross functional areas Experience either worked in the SAP AMS / SAP config and development track Experince in SAP SD mainly covering Understanding on Sales Process, Contract management, Pricing concepts, OTC, Partner Determination, Text Management, Pricing, Taxes, Billing, Credit Management, Back Orders, and Master Data Management (MDM). Experience in configuring Master Data, Document Types (Sales Order Types, Delivery Documents, Billing Documents, Credit and debit memo, etc.) including special order types (Third Party Processing, Consignment Processing, Inter-Company Billing and Inter-company stock transfers), Availability Check, Material Listing/Exclusion, Rebate processing, Deliveries and Post Goods Issues. Experience Required : 2-5 years of experience with 1 implementation on SAP ERP implementation experience and 1 AMS experience worked with global customers Good understanding of SAP Fiori apps Experience in SAP cross-functional areas such as FI/CO, MM/PP Good understanding of all types of order processing models, including B2B, B2C, EDI would be added advantage Experience in project cut-over, successful go-live and client handling during PGLS and alignment with AMS teams will be valued. Good knowledge in the below areas : Electronic data interchange (EDI) : EDI Mapping Integration: Materials Management(MM), Finance, Transportation Management, Management Accounting Experience of third-party application integration using SAP PI/PO such as WM etc.
A4: SAP SD, LE | B4: IS3 | C4: =_xlfn.IFNA(VLOOKUP(B4,Metadata!$G$1:$H$8,2,),"-") -> 5-7 yrs | D4: =_xlfn.CONCAT(A4,"_",B4) -> SAP SD, LE_IS3 | E4: Independently take up and participate in Business workshops, Design End to End solutions . Extensive experience either worked in the SAP AMS / SAP config and development track The candidate must have strong design and implementation knowledge of SAP SD mainly covering Understanding on Sales Process, Contract management, Pricing concepts, OTC, Partner Determination, Text Management, Pricing, Taxes, Billing, Credit Management, Back Orders, and Master Data Management (MDM). Strong experience in configuring Master Data, Document Types (Sales Order Types, Delivery Documents, Billing Documents, Credit and debit memo, etc.) including special order types (Third Party Processing, Consignment Processing, Inter-Company Billing and Inter-company stock transfers), Availability Check, Material Listing/Exclusion, Rebate processing, Deliveries and Post Goods Issues. Exceptional communication and interpersonal skills. Experience Required : Minimum 5-7 years of experience with 1-2 implementation on SAP ERP implementation experience and 2 AMS experience worked with global customers Good understanding of SAP Fiori apps Experience in SAP cross-functional areas such as FI/CO, MM/PP Strong understanding of all types of order processing models, including B2B, B2C, EDI. Business knowledge and solution design experience in all areas of the Order To Cash cycle, including order processing and credit management Proven experience in project cut-over, successful go-live and client handling during PGLS and alignment with AMS teams will be valued. Should also have additional knowledge in the below areas : Electronic data interchange (EDI) : EDI Mapping Integration: Materials Management(MM), Finance, Transportation Management, Management Accounting Experience of third-party application integration using SAP PI/PO such as WM etc.
A5: SAP SD, LE | B5: IS4 | C5: =_xlfn.IFNA(VLOOKUP(B5,Metadata!$G$1:$H$8,2,),"-") -> 7-10 yrs | D5: =_xlfn.CONCAT(A5,"_",B5) -> SAP SD, LE_IS4 | E5: Independently take up and participate in Business workshops, Design End to End solutions with SAP Activate, Agile and DevOps methodologies. Extensive experience either in leading the SAP AMS / leading the SAP config and development track The candidate must have strong design and implementation knowledge of SAP SD mainly covering Understanding on Sales Process, Contract management, Pricing concepts, OTC, Partner Determination, Text Management, Pricing, Taxes, Billing, Credit Management, Back Orders, and Master Data Management (MDM). Strong experience in configuring Master Data, Document Types (Sales Order Types, Delivery Documents, Billing Documents, Credit and debit memo, etc.) including special order types (Third Party Processing, Consignment Processing, Inter-Company Billing and Inter-company stock transfers), Availability Check, Material Listing/Exclusion, Rebate processing, Deliveries and Post Goods Issues. Exceptional communication and interpersonal skills. Experience Required : Minimum 7-10 years of experience with 2-3 implementation on SAP ERP implementation experience Good understanding of SAP Fiori apps Experience in SAP cross-functional areas such as FI/CO, MM/PP Strong understanding of all types of order processing models, including B2B, B2C, EDI. Business knowledge and solution design experience in all areas of the Order To Cash cycle, including order processing and credit management Proven experience in project cut-over, successful go-live and client handling during PGLS and alignment with AMS teams will be valued. Should also have additional knowledge in the below areas : Electronic data interchange (EDI) : EDI Mapping Integration: Materials Management(MM), Finance, Transportation Management, Management Accounting Experience of third-party application integration using SAP PI/PO such as WM etc.
A7: MM, WM + SRM | B7: IS1 | C7: =_xlfn.IFNA(VLOOKUP(B7,Metadata!$G$1:$H$8,2,),"-") -> 0-2 yrs | D7: =_xlfn.CONCAT(A7,"_",B7) -> MM, WM + SRM_IS1 | E7: Experience either in wored in SAP AMS / SAP config and development track Good communication and interpersonal skills. Should be able to learn quickly on the new areas / cross functional areas Should possess natural analytical way of thinking and troubleshooting issues. Technical analysis and documentation of SAP MM/WM application, and it’s integration with other SAP applications like SAP TM, SAP SD, SAP FI and 3rd party applications. Experience Required : Experienced in the areas of SAP ERP MM-PO & MM-IM including Purchase Requisition and Purchase Orders, set up of stock transport orders, Purchase Pricing, PO Release and approvals, Inventory movements and integration to SAP SD (Sales and distribution) SAP Finance, SAP WM (Warehouse Management) etc. Inbound and Outbound IDOCs and Interfaces, Purchasing Output Management and Forms. Understanding in Master data related to procurement like materials, Info records, Business Partners etc. Good understanding of SAP Fiori apps Experienced with 3rd party interfaces and integration. Experience in project cut-over, successful go-live and client handling during PGLS and alignment with AMS teams will be valued. Experience in Third party integration – Movilizer, Barcoding, 3rd party applications would be added advantage
A8: MM, WM + SRM | B8: IS2 | C8: =_xlfn.IFNA(VLOOKUP(B8,Metadata!$G$1:$H$8,2,),"-") -> 2-5 yrs | D8: =_xlfn.CONCAT(A8,"_",B8) -> MM, WM + SRM_IS2 | E8: Experience either in wored in SAP AMS / SAP config and development track Good communication and interpersonal skills. Should be able to learn quickly on the new areas / cross functional areas Should possess natural analytical way of thinking and troubleshooting issues. Technical analysis and documentation of SAP MM/WM application, and it’s integration with other SAP applications like SAP TM, SAP SD, SAP FI and 3rd party applications. Experience Required : Experienced in the areas of SAP ERP MM-PO & MM-IM including Purchase Requisition and Purchase Orders, set up of stock transport orders, Purchase Pricing, PO Release and approvals, Inventory movements and integration to SAP SD (Sales and distribution) SAP Finance, SAP WM (Warehouse Management) etc. Inbound and Outbound IDOCs and Interfaces, Purchasing Output Management and Forms. Understanding in Master data related to procurement like materials, Info records, Business Partners etc. Good understanding of SAP Fiori apps Experienced with 3rd party interfaces and integration. Experience in project cut-over, successful go-live and client handling during PGLS and alignment with AMS teams will be valued. Experience in Third party integration – Movilizer, Barcoding, 3rd party applications would be added advantage
A9: MM, WM + SRM | B9: IS3 | C9: =_xlfn.IFNA(VLOOKUP(B9,Metadata!$G$1:$H$8,2,),"-") -> 5-7 yrs | D9: =_xlfn.CONCAT(A9,"_",B9) -> MM, WM + SRM_IS3 | E9: Independently take up and participate in Business workshops, Design End to End solutions Extensive experience either in wored in SAP AMS / SAP config and development track Should possess natural analytical way of thinking and troubleshooting issues. Good communication and interpersonal skills. Technical analysis and documentation of SAP MM/WM application, and it’s integration with other SAP applications like SAP TM, SAP SD, SAP FI and 3rd party applications. Experience Required : Experienced in the areas of SAP ERP MM-PO & MM-IM including Purchase Requisition and Purchase Orders, set up of stock transport orders, Purchase Pricing, PO Release and approvals, Inventory movements and integration to SAP SD (Sales and distribution) SAP Finance, SAP WM (Warehouse Management) etc. Inbound and Outbound IDOCs and Interfaces, Purchasing Output Management and Forms. Understanding in Master data related to procurement like materials, Info records, Business Partners etc. Good understanding of SAP Fiori apps Experienced with 3rd party interfaces and integration. 5-7 years overall experience and Implementation and delivery experience, which should include at least 1-2 full project lifecycles on SAP ERP and 2 AMS support experience worked across global customers Proven experience in project cut-over, successful go-live and client handling during PGLS and alignment with AMS teams will be valued. Third party integration – Movilizer, Barcoding, 3rd party applications
A10: MM, WM + SRM | B10: IS4 | C10: =_xlfn.IFNA(VLOOKUP(B10,Metadata!$G$1:$H$8,2,),"-") -> 7-10 yrs | D10: =_xlfn.CONCAT(A10,"_",B10) -> MM, WM + SRM_IS4 | E10: Independently take up and participate in Business workshops, Design End to End solutions with SAP Activate, Agile and DevOps methodologies. Extensive experience either in leading the SAP AMS / leading the SAP config and development track Requirements gathering, project planning and management, solution design, configuration and customization of SAP ERP MM-PO and MM-IM, WM Should possess natural analytical way of thinking and troubleshooting issues. Exceptional communication and interpersonal skills. Technical analysis and documentation of SAP MM/WM application, and it’s integration with other SAP applications like SAP TM, SAP SD, SAP FI and 3rd party applications. Experience Required : Highly experienced in the areas of SAP ERP MM-PO & MM-IM including Purchase Requisition and Purchase Orders, set up of stock transport orders, Purchase Pricing, PO Release and approvals, Inventory movements and integration to SAP SD (Sales and distribution) SAP Finance, SAP WM (Warehouse Management) etc. Inbound and Outbound IDOCs and Interfaces, Purchasing Output Management and Forms. Understanding in Master data related to procurement like materials, Info records, Business Partners etc. Good understanding of SAP Fiori apps Experienced with 3rd party interfaces and integration. 7-10 years overall experience and Implementation and delivery experience, which should include at least 2-3 full project lifecycles on SAP ERP. Proven experience in project cut-over, successful go-live and client handling during PGLS and alignment with AMS teams will be valued. Third party integration – Movilizer, Barcoding, 3rd party applications
A11: MM, WM + SRM | B11: IS5 | C11: =_xlfn.IFNA(VLOOKUP(B11,Metadata!$G$1:$H$8,2,),"-") -> 10-15 yrs | D11: =_xlfn.CONCAT(A11,"_",B11) -> MM, WM + SRM_IS5 | E11: Independently take up and participate in Business workshops, Design End to End solutions with SAP Activate, Agile and DevOps methodologies. Extensive experience either in leading the SAP AMS / leading the SAP config and development track Requirements gathering, project planning and management, solution design, configuration and customization of SAP ERP MM-PO and MM-IM, WM Should possess natural analytical way of thinking and troubleshooting issues. Exceptional communication and interpersonal skills. Technical analysis and documentation of SAP MM/WM application, and it’s integration with other SAP applications like SAP TM, SAP SD, SAP FI and 3rd party applications. Experience Required : Highly experienced in the areas of SAP ERP MM-PO & MM-IM including Purchase Requisition and Purchase Orders, set up of stock transport orders, Purchase Pricing, PO Release and approvals, Inventory movements and integration to SAP SD (Sales and distribution) SAP Finance, SAP WM (Warehouse Management) etc. Inbound and Outbound IDOCs and Interfaces, Purchasing Output Management and Forms. Understanding in Master data related to procurement like materials, Info records, Business Partners etc. Good understanding of SAP Fiori apps Experienced with 3rd party interfaces and integration. 10+ years overall experience and Implementation and delivery experience, which should include at least 2-3 full project lifecycles on SAP ERP. Proven experience in project cut-over, successful go-live and client handling during PGLS and alignment with AMS teams will be valued. Third party integration – Movilizer, Barcoding, 3rd party applications
A13: FI, CO | B13: IS1 | C13: =_xlfn.IFNA(VLOOKUP(B13,Metadata!$G$1:$H$8,2,),"-") -> 0-2 yrs | D13: =_xlfn.CONCAT(A13,"_",B13) -> FI, CO_IS1 | E13: Should possess natural analytical way of thinking and troubleshooting issues. Good communication and interpersonal skills. Should be able to learn quickly on the new areas / cross functional areas Pls look for unique roles as follows : 1. SAP FICO, 2. SAP Treasury Managemant, 3. SAP Cash Management, 4. SAP Central Finance Experience Required : 0-2 years of experience with 1 implementation in SAP ERP and 1 AMS expereince worked with Global customer Experience in SAP cross-functional areas such as SD, MM/PP, PS Good knowledge in all types of order processing models, including B2B, B2C, EDI. Experience in project cut-over, successful go-live and client handling during PGLS and alignment with AMS teams will be valued. Experience in FI: G/L, AP, AR, Treasury, Assets, Closing and Reporting, CO: CCA, PCA, Internal order, CO-PA, CO-PC Experience in Controlling submodules like CO-Product Costing and CO-Profitability Analysis and CO-Profit center Accounting is must. SAP Functional configuration expertise in General Ledger (FI- GL), Controlling (CO), Accounts Receivable (AR), Accounts Payable (AP), Asset Accounting (AA), Project Systems (PS) Profitability Analysis (PA), New GL, Experience in Financial Month end Activity, Financial Closing Cockpit(Task template, Task list) and Intercompany reconciliation process. Good to have knowledge in Fiori Apps, Fiori Launchpad, Fiori Launchpad Designer configuration & feature and Fiori application types.
A14: FI, CO | B14: IS2 | C14: =_xlfn.IFNA(VLOOKUP(B14,Metadata!$G$1:$H$8,2,),"-") -> 2-5 yrs | D14: =_xlfn.CONCAT(A14,"_",B14) -> FI, CO_IS2 | E14: Should possess natural analytical way of thinking and troubleshooting issues. Good communication and interpersonal skills. Should be able to learn quickly on the new areas / cross functional areas Pls look for unique roles as follows : 1. SAP FICO, 2. SAP Treasury Managemant, 3. SAP Cash Management, 4. SAP Central Finance Experience Required : 2-5 years of experience with 1 implementation in SAP ERP and 1 AMS expereince worked with Global customer Experience in SAP cross-functional areas such as SD, MM/PP, PS Good knowledge in all types of order processing models, including B2B, B2C, EDI. Experience in project cut-over, successful go-live and client handling during PGLS and alignment with AMS teams will be valued. Experience in FI: G/L, AP, AR, Treasury, Assets, Closing and Reporting, CO: CCA, PCA, Internal order, CO-PA, CO-PC Experience in Controlling submodules like CO-Product Costing and CO-Profitability Analysis and CO-Profit center Accounting is must. SAP Functional configuration expertise in General Ledger (FI- GL), Controlling (CO), Accounts Receivable (AR), Accounts Payable (AP), Asset Accounting (AA), Project Systems (PS) Profitability Analysis (PA), New GL, Experience in Financial Month end Activity, Financial Closing Cockpit(Task template, Task list) and Intercompany reconciliation process. Good to have knowledge in Fiori Apps, Fiori Launchpad, Fiori Launchpad Designer configuration & feature and Fiori application types.
A15: FI, CO | B15: IS3 | C15: =_xlfn.IFNA(VLOOKUP(B15,Metadata!$G$1:$H$8,2,),"-") -> 5-7 yrs | D15: =_xlfn.CONCAT(A15,"_",B15) -> FI, CO_IS3 | E15: Independently take up and participate in Business workshops, Design End to End solutions with SAP Should possess natural analytical way of thinking and troubleshooting issues. Good communication and interpersonal skills. Pls look for unique roles as follows : 1. SAP FICO, 2. SAP Treasury Managemant, 3. SAP Cash Management, 4. SAP Central Finance Experience Required : Minimum 5-7 years of experience with 1-2 implementation in SAP ERP and 3 AMS expereince worked with Global customer Experience in SAP cross-functional areas such as SD, MM/PP, PS Strong understanding of all types of order processing models, including B2B, B2C, EDI. Proven experience in project cut-over, successful go-live and client handling during PGLS and alignment with AMS teams will be valued. Strong experience in FI: G/L, AP, AR, Treasury, Assets, Closing and Reporting, CO: CCA, PCA, Internal order, CO-PA, CO-PC Very good experience in Controlling submodules like CO-Product Costing and CO-Profitability Analysis and CO-Profit center Accounting is must. SAP Functional configuration expertise in General Ledger (FI- GL), Controlling (CO), Accounts Receivable (AR), Accounts Payable (AP), Asset Accounting (AA), Project Systems (PS) Profitability Analysis (PA), New GL, Experience in Financial Month end Activity, Financial Closing Cockpit(Task template, Task list) and Intercompany reconciliation process. Experience with Simple Finance / Central Finance exposure will be given preference Project experience activities to include preparation, synchronization, conversion and post processing, table mapping for HANA, comprehensive knowledge of BP roles and functionality of S4 HANA Finance is preferred. Should have an overview of Deployment option for S4H. Good to have knowledge in Fiori Apps, Fiori Launchpad, Fiori Launchpad Designer configuration & feature and Fiori application types.
... A89: PLM (MDG and ECC) | B89: IS4 | C89: =_xlfn.IFNA(VLOOKUP(B89,Metadata!$G$1:$H$8,2,),"-") -> 7-10 yrs | D89: =_xlfn.CONCAT(A89,"_",B89) -> PLM (MDG and ECC)_IS4 | E89: At least 7 years’ experience with SAP implementation and SAP services management with large global organisations with large SAP installations across multiple geographies. Have onsite delivery experience around 6+ yeaear preferably in APAC and Europe Extensive experience in delivering Agile, DevOps, Activate methology Should have Delivery management experience of 15+ years in SAP implementation, Rollout, Managed Services for manufacturing/CPG domain Lead the assessment and gap analysis of MDM projects, test and validate all releases and regression Support business users with MDG data (customer, pricing, vendor, finance and accounting, APO, HR, workflow processes) Manages the analysis and execution of new master data setup or data changes Effectively coordinate with internal team, partners and Customer's data governanace COE to manage the day-to-day maintenance requirement Automates access control the business functions can see and act upon the data in accordance with their job function Proactively seeks, analyses, adminsters and communicates actionable data to the customer around data management
A91: SAP Consultant | B91: IS6 | C91: =_xlfn.IFNA(VLOOKUP(B91,Metadata!$G$1:$H$8,2,),"-") -> 20+ yrs | D91: =_xlfn.CONCAT(A91,"_",B91) -> SAP Consultant_IS6
A93: SAP PO/PI/CPI | B93: IS1 | C93: =_xlfn.IFNA(VLOOKUP(B93,Metadata!$G$1:$H$8,2,),"-") -> 0-2 yrs | D93: =_xlfn.CONCAT(A93,"_",B93) -> SAP PO/PI/CPI_IS1 | E93: 0-2 yrs of experience in implement and deploy SAP Cloud Integration Suite solutions (CPI), SAP PO, SAP PI to achieve defined business goals Maintain skills in SAP applications process design and configuration Work as part of small teams and/or work efforts (if in an individual contributor role) to deliver integration solutions to customers. Production Support of integration processes as needed Technical configuration for domain areas Escalation point for solution design or troubleshooting with outside service partners Supporting and implementing technical integrations with a variety of global 3rd party applications. Must be a team player to collaboratively and effectively deliver high quality work product and communicate with others on multi-disciplinary teams. Responsible for troubleshooting technical problems. Map the business process to SAP Technologies-CPI, BOOMI, SAP Fiori, SAP UI5,etc.
A94: SAP PO/PI/CPI | B94: IS2 | C94: =_xlfn.IFNA(VLOOKUP(B94,Metadata!$G$1:$H$8,2,),"-") -> 2-5 yrs | D94: =_xlfn.CONCAT(A94,"_",B94) -> SAP PO/PI/CPI_IS2 | E94: 2-5 yrs of experience in Design, implement and deploy SAP Cloud Integration Suite solutions (CPI), SAP PO, SAP PI to achieve defined business goals Maintain skills in SAP applications process design and configuration SAP application design, development, integration, testing, deployment and technical architecture Work as part of small teams and/or work efforts (if in an individual contributor role) to deliver integration solutions to customers. Implement or deploy capabilities as required: End-to-End process design, testing strategy, cutover plans, training, etc. Production Support of integration processes as needed Technical configuration for domain areas Escalation point for solution design or troubleshooting with outside service partners Supporting and implementing technical integrations with a variety of global 3rd party applications. Understand end-to-end Business Processes Must be a team player to collaboratively and effectively deliver high quality work product and communicate with others on multi-disciplinary teams. Responsible for successful end to end delivery. Responsible for troubleshooting technical problems. Map the business process to SAP Technologies-CPI, BOOMI, SAP Fiori, SAP UI5,etc.
A95: SAP PO/PI/CPI | B95: IS3 | C95: =_xlfn.IFNA(VLOOKUP(B95,Metadata!$G$1:$H$8,2,),"-") -> 5-7 yrs | D95: =_xlfn.CONCAT(A95,"_",B95) -> SAP PO/PI/CPI_IS3 | E95: 5-7 yrs of experience in Design, implement and deploy SAP Cloud Integration Suite solutions (CPI), SAP PO, SAP PI to achieve defined business goals Maintain skills in SAP applications process design and configuration SAP application design, development, integration, testing, deployment and technical architecture Work as part of small teams and/or work efforts (if in an individual contributor role) to deliver integration solutions to customers. Implement or deploy capabilities as required: End-to-End process design, testing strategy, cutover plans, training, etc. Production Support of integration processes as needed Technical configuration for domain areas Escalation point for solution design or troubleshooting with outside service partners Supporting and implementing technical integrations with a variety of global 3rd party applications. Understand end-to-end Business Processes Must be a team player to collaboratively and effectively deliver high quality work product and communicate with others on multi-disciplinary teams. Responsible for successful end to end delivery. Responsible for troubleshooting technical problems. Map the business process to SAP Technologies-CPI, BOOMI, SAP Fiori, SAP UI5,etc.
A96: SAP PO/PI/CPI | B96: IS4 | C96: =_xlfn.IFNA(VLOOKUP(B96,Metadata!$G$1:$H$8,2,),"-") -> 7-10 yrs | D96: =_xlfn.CONCAT(A96,"_",B96) -> SAP PO/PI/CPI_IS4 | E96: 7+ years of experince in SAP integration including SAP PO, PI and CPI Analyze integration requirements, design and implement complex, state-of-the-art end-to-end integration scenarios across multiple technologies and multiple modules. Define integration architectures and API strategies. Interface design and implementation based on SAP Cloud Platform Integration Suite and SAP Process Orchestration. Integration of cloud solutions and platforms (SAP, Salesforce, Azure, AWS), IoT services and external business partners. Evaluate new SAP technologies and supporting building know-how in these areas, which are integrated into cbs processes. Technical integration consulting and development as part of global SAP ECC, S/4HANA or C/4HANA implementation projects. Be responsible for cbs projects and customers in the technology area as well as engage in pre-sales support in all kinds of SAP technology topics. Act as a technical team lead for the requested deliverables which includes adhering to the timeline, effort and assuring quality. Collaboration with the onsite team. Coach colleagues in functional, technical, and methodic topics. Sharing knowledge and experience with the colleagues. Contribute to cbs best practices and methodologies. Desire for a dynamic and prestigious work environment.
A97: SAP PO/PI/CPI | B97: IS5 | C97: =_xlfn.IFNA(VLOOKUP(B97,Metadata!$G$1:$H$8,2,),"-") -> 10-15 yrs | D97: =_xlfn.CONCAT(A97,"_",B97) -> SAP PO/PI/CPI_IS5 | E97: 10+ years of experince in SAP integration including SAP PO, PI and CPI Analyze integration requirements, design and implement complex, state-of-the-art end-to-end integration scenarios across multiple technologies and multiple modules. Define integration architectures and API strategies. Interface design and implementation based on SAP Cloud Platform Integration Suite and SAP Process Orchestration. Integration of cloud solutions and platforms (SAP, Salesforce, Azure, AWS), IoT services and external business partners. Evaluate new SAP technologies and supporting building know-how in these areas, which are integrated into cbs processes. Technical integration consulting and development as part of global SAP ECC, S/4HANA or C/4HANA implementation projects. Be responsible for cbs projects and customers in the technology area as well as engage in pre-sales support in all kinds of SAP technology topics. Act as a technical team lead for the requested deliverables which includes adhering to the timeline, effort and assuring quality. Collaboration with the onsite team. Coach colleagues in functional, technical, and methodic topics. Sharing knowledge and experience with the colleagues. Contribute to cbs best practices and methodologies.
A98: SAP PO/PI/CPI | B98: I5+ | C98: =_xlfn.IFNA(VLOOKUP(B98,Metadata!$G$1:$H$8,2,),"-") -> 15 - 20 yrs | D98: =_xlfn.CONCAT(A98,"_",B98) -> SAP PO/PI/CPI_I5+ | E98: 15+ years of experince in SAP integration including SAP PO, PI and CPI Analyze integration requirements, design and implement complex, state-of-the-art end-to-end integration scenarios across multiple technologies and multiple modules. Define integration architectures and API strategies. Interface design and implementation based on SAP Cloud Platform Integration Suite and SAP Process Orchestration. Integration of cloud solutions and platforms (SAP, Salesforce, Azure, AWS), IoT services and external business partners. Evaluate new SAP technologies and supporting building know-how in these areas, which are integrated into cbs processes. Technical integration consulting and development as part of global SAP ECC, S/4HANA or C/4HANA implementation projects. Be responsible for cbs projects and customers in the technology area as well as engage in pre-sales support in all kinds of SAP technology topics. Act as a technical team lead for the requested deliverables which includes adhering to the timeline, effort and assuring quality. Collaboration with the onsite team. Coach colleagues in functional, technical, and methodic topics. Sharing knowledge and experience with the colleagues. Contribute to cbs best practices and methodologies.
A100: Mulesoft | B100: IS1 | C100: =_xlfn.IFNA(VLOOKUP(B100,Metadata!$G$1:$H$8,2,),"-") -> 0-2 yrs | D100: =_xlfn.CONCAT(A100,"_",B100) -> Mulesoft_IS1 | E100: Required Skills: Responsible for building integration solutions on the MuleSoft Anypoint Platform with design of specifications, design and development of APIs meeting, deployment, testing and Support. 0- 2 yrs of Experience required in Mulesoft Development. Experience working directly with technical and business teams. Knowledge of SDLC, IT governance and operations. Experience in packaging and deploying MuleSoft applications. Experience working with CI/CD tools like GitHub, Maven, Azure DevOps etc. Experience with messaging platforms Anypoint MQ,IBM MQ etc. Experience working with Mule Connectors ( Standard & Custom). Bachelors degree required. Good verbal and written communication skills are essential. Strong critical thinking and problem-solving skills. Experience working with overseas teams.
A101: Mulesoft | B101: IS2 | C101: =_xlfn.IFNA(VLOOKUP(B101,Metadata!$G$1:$H$8,2,),"-") -> 2-5 yrs | D101: =_xlfn.CONCAT(A101,"_",B101) -> Mulesoft_IS2 | E101: Required Skills: Responsible for building integration solutions on the MuleSoft Anypoint Platform with design of specifications, design and development of APIs meeting, deployment, testing and Support. 2- 5 yrs of Experience required in Mulesoft Development. Experience working directly with technical and business teams. Knowledge of SDLC, IT governance and operations. Experience in packaging and deploying MuleSoft applications. Experience working with CI/CD tools like GitHub, Maven, Azure DevOps etc. Experience with messaging platforms Anypoint MQ,IBM MQ etc. Experience working with Mule Connectors ( Standard & Custom). Bachelors degree required. Good verbal and written communication skills are essential. Strong critical thinking and problem-solving skills. Experience working with overseas teams. MuleSoft developer certified shall be preferred
A102: Mulesoft | B102: IS3 | C102: =_xlfn.IFNA(VLOOKUP(B102,Metadata!$G$1:$H$8,2,),"-") -> 5-7 yrs | D102: =_xlfn.CONCAT(A102,"_",B102) -> Mulesoft_IS3 | E102: 5+ years of software development experience with extensive integration experience in MuleSoft 4+ years of development experience using MuleSoft suite of products - Any point Platform, Design Center, Connectors, Exchange, Runtime manager and API Management tools. 2+ years of application development experience. Strong technical knowledge and work experience in implementing integrations with Web services / SOAP / RESTful/gRPC/ Graphql / file based integration patterns and use of different Mule connectors (Any point MQ, Kafka, Azure Event Hub, File, Http/Https, Siebel, ServiceNow, SAP SuccessFactors, Salesforce, Oracle EBS Connector etc.) Experience in developing Microservices architecture-based API, Event Driven and Batch style integration patterns Experience in Java 1.8, Data Weave, JSON, Open API and RAML is required in a cloud or hybrid architecture platfor Business process knowledge and work experience with ERP / Cloud systems within Sales, Marketing, Finance and CRM domains. Experience with DevOps culture and CI/CD tools Participate in proof-of-concept to demonstrate feasibility. Experience of security models, encryption, routing, transformations, error handling, logging, and testing frameworks. Working experience on Agile, Azure Devops and SDLC processes. Good communication, analytical skills.
A103: Mulesoft | B103: IS4 | C103: =_xlfn.IFNA(VLOOKUP(B103,Metadata!$G$1:$H$8,2,),"-") -> 7-10 yrs | D103: =_xlfn.CONCAT(A103,"_",B103) -> Mulesoft_IS4 | E103: 7+ years of Overall experience and Experience in architecture, design and implementation of MuleSoft integration and integration experience along with Java based solutions (refer mandatory skills) Candidate should have 4+ years of Architecture design and consulting skills Extensive experience in API's / Web services / SOA development Extensive experience with successful implementations of highly scalable and highly available systems Experience with agile/DevOps development processes Skills Required Expertise in Mulesoft, Expertise in Java, Web services, APIs, SOA and any RDBMS Messaging - JMS APIs, ActiveMQ etc Development tools (Maven, Ant, Jira, Eclipse) Any source versioning control tools expertise Good knowledge on OOPS concepts and design/integration patterns
A104: Mulesoft | B104: IS5 | C104: =_xlfn.IFNA(VLOOKUP(B104,Metadata!$G$1:$H$8,2,),"-") -> 10-15 yrs | D104: =_xlfn.CONCAT(A104,"_",B104) -> Mulesoft_IS5 | E104: 10+ years of experience as an Architect for developing API, ESB, Middleware tools based messaging or EDI or customer integration. Application developed involves communication with both .Net, Java, or Microservices based new or existing legacy platforms Excellent knowledge and hands-on experience with multiple platforms and related technologies: MuleSoft, any Opensource ESB, .Net WebAPI, Java Messaging Service, Apache Kafka, IBM CP4I, Rabbit MQ. Experience with common architectures like Hub-Spoke, Federated ESB, Open API, Queues, Streaming Architecture Knowledge of common software engineering practices Requirements Engineering, Design Patterns, Code Analysis, Performance, DevOps (CI/CD) and architecture modelling practices (UML, Swagger, etc.) Architect the solution for web and hybrid enterprise applications for several platforms (Mobile, Web, B2C/ B2B, Data systems) Know the best practices and risks in terms of security. Always keen to learn new things, share your knowledge, embrace change and learn from past experiences. Integrate with other application developed in Cloud or on-premise Collaborate with Product Team and Application team Review code for well-designed components and testable code Integrate software components into a fully functional software system Troubleshoot, debug and upgrade existing integration Comply with project plans Comply to industry best practices and standards Should possess excellent time management skills
A106: Talend | B106: IS1 | C106: =_xlfn.IFNA(VLOOKUP(B106,Metadata!$G$1:$H$8,2,),"-") -> 0-2 yrs | D106: =_xlfn.CONCAT(A106,"_",B106) -> Talend_IS1 | E106: 0-2 yrs of Talend developer experience , ETL development , RDBMS , SQL , TAC, TMC. • Knowledge and hands-on experience with ETL development • Hands on experience on implementing different loading strategies like SCD1 and SCD2, Table/ partition refresh, insert update, Swap Patriation using Talend. • Experience in Consuming and writing data from and to Flat files, RDMBS systems, MPPS, Jason and XML using Talend • Experience on RDBMS systems and concepts • Expertise in writing and complex SQL queries and developing Database components including creating views, stored procedures, triggers etc. • Create test cases and perform unit testing of ETL Jobs using Talend. • Hands on experience on ETL jobs orchestration using Talend. • Hands on experience on creating Triggers on TAC server for Scheduling the Talend jobs • Experience on creating batch level processing, parallel process using Talend. • Analytical mind with a problem-solving and debugging skills. • Excellent Communication Skills • Awareness of Replication, Synchronization and Disaster Management techniques • Awareness of Data Quality Management
... A160: Integration Service Delivery Manager | B160: IS5 | C160: =_xlfn.IFNA(VLOOKUP(B160,Metadata!$G$1:$H$8,2,),"-") -> 10-15 yrs | D160: =_xlfn.CONCAT(A160,"_",B160) -> Integration Service Delivery Manager_IS5 | E160: 10+ years of experince in SAP integration including SAP PO, PI and CPI Analyze integration requirements, design and implement complex, state-of-the-art end-to-end integration scenarios across multiple technologies and multiple modules. Define integration architectures and API strategies. Interface design and implementation based on SAP Cloud Platform Integration Suite and SAP Process Orchestration. Integration of cloud solutions and platforms (SAP, Salesforce, Azure, AWS), IoT services and external business partners. Evaluate new SAP technologies and supporting building know-how in these areas, which are integrated into cbs processes. Technical integration consulting and development as part of global SAP ECC, S/4HANA or C/4HANA implementation projects. Be responsible for cbs projects and customers in the technology area as well as engage in pre-sales support in all kinds of SAP technology topics. Act as a technical team lead for the requested deliverables which includes adhering to the timeline, effort and assuring quality. Collaboration with the onsite team. Coach colleagues in functional, technical, and methodic topics. Sharing knowledge and experience with the colleagues. Contribute to cbs best practices and methodologies.
A161: Cloud DM-Onsite/KL | B161: IS5 | C161: 12-20 years | D161: =_xlfn.CONCAT(A161,"_",B161) -> Cloud DM-Onsite/KL_IS5 | E161: Service Delivery Manager-Cloud Services ITC is looking for the Program Manager/Service Delivery Manager to manage a portfolio of customer migration assessments/Managed services for Cloud platforms with 12-20 years of experience across a range of levels from different backgrounds and with various skills and expertise. In this role who can work with Customers, Delivery team, and Cloud Partners to deliver data-backed assessments to customers for migrating their current on-premises workloads to the Cloud. We are seeking the one who can demonstrate the below skills or those who are keen to gain them: Certifications Any competitive Cloud Practitioner or Associate Solution Architecture Certification Professional certification on Project/Program Management is highly desirable Azure or AWS Administration or Architect level certification would be added advantage Roles and Responsibilities Program Manager should have good experience in managing large AWS/Azure implementation migration programs and running managed service delivery. The Program Manager serves a key upfront role on these assessments by ensuring that customers are choosing the correct tools and programs throughout the planning and execution of their migration, as well as serving as a contact person to reduce friction and roadblocks throughout the customer’s migration journey and running efficient service delivery. Gather requirements from customers regarding desired outcomes of the assessment to ensure the appropriate tools and teams are included. Ensure that an assessment is running smoothly and on time, following up to offer extra assistance when required. Dealing with stakeholders, plan, organize, schedule, control, and monitor projects to ensure timely completion, cost effectiveness, and customer satisfaction. Proactively identifies potential delivery issues and drives resolution to avoid customer impact. Always look for area of opportunity for automation adoption and optimize resource efforts, efficiency and drive ROI Identifies scope changes from the original plan or agreement and escalates to the management team. Setting up the team and mentoring them Works directly with technical team and ensure project success and managing the team. Develop, maintain, and manage relationships with client executives and engagement sponsors and provides complex metrics and reporting support to all relevant stakeholders. Knowledge working closely with ServiceNow/Jira or any other project management software. Excellent oral and written communications skills as necessary to communicate, negotiate, advice, or resolve issues that are highly complex including the ability to communicate technical information to nontechnical users effectively. Manage the intake process for all new Migration assessments. Position and propose the inclusion of partners for an assessment, when applicable. Provide high-level demonstrations & overviews of migration tools to outline options to internal and external customers. Provide a single point of escalation for teams needing Migration assistance, or for high profile assessments. Should be well versed with building confidence, trust and grabbing more business opportunities
A162: Azure Architect-Onsite/KL | B162: IS5 | C162: 10-15 Years | D162: =_xlfn.CONCAT(A162,"_",B162) -> Azure Architect-Onsite/KL_IS5 | E162: ITC is looking for Cloud Solution Architects with 10-15 years of experience across a range of levels from different backgrounds and with various skills and expertise. Understanding that there are many paths to acquiring the skills needed to be a successful Cloud Solution Architect, we are seeking the one who can demonstrate the below skills or those who are keen to gain them: Certifications Azure Certified Solutions Architect Associate Azure Certified Solutions Architect Professional Roles and Responsibilities Participate in technical discussion, provide consultative services to customer, guide the team based on requirements for delivery, Provide Azure technical design and thought leadership. Must have experience with designing and deploying solutions in Azure at enterprise scale, with good automation skills, Understand the customers business & application requirements and translate them into system / technical requirements. Experience with private public cloud architectures, pros/cons, and migration considerations, implementation features (OS, multi-tenancy, virtualization, orchestration, elastic scalability Extensive hands-on experience implementing infra migration, data migration and data processing using Azure services: Networking, Windows/Linux virtual machines, Container, Storage, ELB, Autoscaling, Azure Functions, Serverless Architecture, ARM Templates, Azure SQL DB/DW, Data Factory, Azure Stream Analytics, Azure Analysis Service - Must have experience in Azure IaaS and Azure active directory Proven experience assessing client’s workloads and technology landscape for Cloud suitability, develop business case and Cloud adoption roadmap Experience in working RFP's Proposals, Solutions, defining new architectures and ability to drive project from architecture standpoint Knowledge of best practices and market trends pertaining to Cloud and overall industry to provide thought leadership (seminars, whitepapers etc.,) and mentor team to build necessary competency. Ability to quickly establish credibility and trustworthiness with key stakeholders in client organization. Well versed with third party DevOps such as Jenkins, Bitbucket, docker repository, terraform, and ansible, Azure Security policy, Azure DevOps, AKS, Azure WAF, networking and ingress controller, good knowledge of working with Kafka, Datadog is added advantage Ensure success in designing, building, and migrating applications, software, and services on the Azure platform. end-to-end architecture, networking, provisioning, and management Educate customers on best practices to ensure their solutions are designed for successful deployment in the cloud. Demonstrate leadership ability to back decisions with research and the "why," and articulate several options, the pros and cons for each, and a recommendation. Understand the data requirements, source data landscape of the project and architect the solution with required solution components. Hands-on experience in designing cost-efficient, fault-tolerant, and scalable distributed systems on Azure. Understand the data processing requirements like batch computing, stream computing needs and design the solution on Azure stack
A163: AWS Architect-Onsite/Mexico | B163: IS4 | C163: 10-15 Years | D163: =_xlfn.CONCAT(A163,"_",B163) -> AWS Architect-Onsite/Mexico_IS4 | E163: TC Infotech is looking for 10-15 years of experienced and highly motivated architects who possess technical depth and strong interpersonal skills. As an AWS solution architect, you will lead technical workshops, advise customers on architectural and strategic IT decisions and design highly scalable, flexible and resilient cloud architectures that address customer business challenges. As a trusted customer advocate, the solutions architect will help organizations understand best practices around advanced AWS cloud-based solutions. Certification requirements: AWS Certified Solutions Architect Associate AWS Certified Solutions Architect Professional Roles and Responsibilities Understand technical, business & application requirements from client discussions, RFP's and Translate them into system / technical requirements and build Proposals, Solutions, Cloud suitability, develop business case and Cloud adoption roadmap Good Exp in driving and running cloud managed services for larger workloads with multi cloud platforms & Multi vendor involvment and driving cloud optimization and efficiency Lead technical workshops and advise customers on architectural and strategic IT decisions, end-to-end architecture, networking, provisioning, and management Develop AWS technical design, thought leadership, architecture blueprints and detailed documentation. Create bill of materials, including required Cloud Services (such as EC2, S3 etc.) and tools. Proven knowledge of AWS platform and tools Design, Setup and oversee the overall AWS Virtual Private Cloud VPC environment including server instance, storage instances, subnets, availability zones, network architecture and HA / DR strategies etc. Ensure success in designing, building and migrating applications, software, and services on the AWS platform. Define Migration strategy to move application to cloud Educate customers on best practices to ensure their solutions are designed for successful deployment in the cloud. Demonstrate knowledge of cloud architecture and implementation features (OS, multi-tenancy, virtualization, orchestration, elastic scalability) Demonstrate leadership ability to back decisions with research and the "why," and articulate several options, the pros and cons for each, and a recommendation. Hands-on experience in designing cost-efficient, fault-tolerant and scalable distributed systems on AWS. Understand the data processing requirements like batch computing, stream computing needs and design the solution on AWS stack. Experience in defining new architectures and ability to drive project from architecture standpoint, continuously focus on project delivery excellence and customer satisfaction Knowledge of best practices and market trends pertaining to Cloud and overall industry to provide thought leadership (seminars, whitepapers etc.,) and mentor team to build necessary competency. Ability to quickly establish credibility and trustworthiness with key stakeholders in client organization. Finalizing and preparing the templates of design documents, data flows, mapping documents, implementation, and maintenance plans. Set up process, services and tools around the cloud. Produce design documents for effectively hand over infrastructure architectures to Operations teams for successful systems engineering and implementation.
A164: Azure SME/Technical Lead | B164: IS4 | C164: 6-12 Years | D164: =_xlfn.CONCAT(A164,"_",B164) -> Azure SME/Technical Lead _IS4 | E164: Azure SME/Technical Lead ITC is looking for Cloud SME/Technical Lead with 6-12 years of experience across a range of levels from different backgrounds and with various skills and expertise. Understanding that there are many paths to acquiring the skills needed to be a successful Cloud Architect, we are seeking the one who can demonstrate the below skills or those who are keen to gain them: Certifications: - Microsoft Azure AZ-104 required Microsoft AZ-305 is a plus Other Clouds like AWS and VMWare exp would be good to have Roles and Responsibilities: - At least 6 -12 years of experience with troubleshooting, managing and monitoring Azure workloads and services Good knowledge of Azure IaaS (VMs, VNET, NSG Rules, VPN Gateways and Express Route). Creating, deploying, configuring and scaling applications on Windows/Linux Azure PaaS Experience with Azure Policy development via ARM or Terraform. Extensive hands-on experience implementing infra migration, data migration and data processing using Azure services: Networking, Windows/Linux virtual machines, Container, Storage, LB, Autoscaling, Azure Functions, Serverless Architecture, ARM Templates, Azure SQL DB/DW, Data Factory, Azure Stream Analytics, Azure Analysis Proven experience within client facing roles with ability to work creatively in a problem-solving environment Hands on experience on Azure App Service Model (Web Apps, Mobile Apps, API Apps and Web Jobs). Hands on experience on Azure storage services like SQL DB, Tables, Files, Blobs and Azure API Management Service. Experience on cloud automation, Infrastructure as Code, ARM and Terraform. Good understanding of windows server (2008/12/16) administration, DNS, DHCP and User profiles Good to have Experience of executing cloud native projects in Azure with DevOps using VSTS along with Microsoft as well as Open-Source Tools. Good understanding on MS CAF and well architected framework Good to have Azure virtual Desktop or VDI exp. Hands on experience on Azure Integration services like Service Bus and Event Hubs. Must have experience with designing and deploying solutions in Azure at enterprise scale, with good automation skills, Understand the customers business & application requirements and translate them into system / technical requirements. Experience with private public cloud architectures, pros/cons, and migration considerations, implementation features (OS, multi-tenancy, virtualization, orchestration, elastic scalability Ability to quickly establish credibility and trustworthiness with key stakeholders in client organization. Hands-on experience in designing cost-efficient, fault-tolerant, and scalable distributed systems on Azure.
A165: Azure SME/Technical Lead | B165: IS4 | C165: 6-12 Years | D165: =_xlfn.CONCAT(A165,"_",B165) -> Azure SME/Technical Lead _IS4 | E165: Azure SME/Technical Lead ITC is looking for Cloud SME/Technical Lead with 6-12 years of experience across a range of levels from different backgrounds and with various skills and expertise. Understanding that there are many paths to acquiring the skills needed to be a successful Cloud Architect, we are seeking the one who can demonstrate the below skills or those who are keen to gain them: Certifications: - Microsoft Azure AZ-104 required Microsoft AZ-305 is a plus Other Clouds like AWS and VMWare exp would be good to have Roles and Responsibilities: - At least 6 -12 years of experience with troubleshooting, managing and monitoring Azure workloads and services Good knowledge of Azure IaaS (VMs, VNET, NSG Rules, VPN Gateways and Express Route). Creating, deploying, configuring and scaling applications on Windows/Linux Azure PaaS Experience with Azure Policy development via ARM or Terraform. Extensive hands-on experience implementing infra migration, data migration and data processing using Azure services: Networking, Windows/Linux virtual machines, Container, Storage, LB, Autoscaling, Azure Functions, Serverless Architecture, ARM Templates, Azure SQL DB/DW, Data Factory, Azure Stream Analytics, Azure Analysis Proven experience within client facing roles with ability to work creatively in a problem-solving environment Hands on experience on Azure App Service Model (Web Apps, Mobile Apps, API Apps and Web Jobs). Hands on experience on Azure storage services like SQL DB, Tables, Files, Blobs and Azure API Management Service. Experience on cloud automation, Infrastructure as Code, ARM and Terraform. Good understanding of windows server (2008/12/16) administration, DNS, DHCP and User profiles Good to have Experience of executing cloud native projects in Azure with DevOps using VSTS along with Microsoft as well as Open-Source Tools. Good understanding on MS CAF and well architected framework Good to have Azure virtual Desktop or VDI exp. Hands on experience on Azure Integration services like Service Bus and Event Hubs. Must have experience with designing and deploying solutions in Azure at enterprise scale, with good automation skills, Understand the customers business & application requirements and translate them into system / technical requirements. Experience with private public cloud architectures, pros/cons, and migration considerations, implementation features (OS, multi-tenancy, virtualization, orchestration, elastic scalability Ability to quickly establish credibility and trustworthiness with key stakeholders in client organization. Hands-on experience in designing cost-efficient, fault-tolerant, and scalable distributed systems on Azure.
A166: AWS SME | B166: IS4 | C166: 6-12 Years | D166: =_xlfn.CONCAT(A166,"_",B166) -> AWS SME_IS4 | E166: AWS SME / Consultant ITC Infotech is looking for AWS consultant with 6-10 years of experience in implementing cloud platforms as per solution. You will work with clients to understand the requirements and provide required support to AWS cloud platform and suggest required changes as per industry standard and implement improvements in the client environments and provide support. If you thrive in a dynamic, collaborative workplace, ITC provides an environment where you will be challenged and inspired every single day. And if you relish the freedom to bring creative, thoughtful solutions to the table, there’s no limit to what you can accomplish here. Certifications: AWS Certified Solutions Architect Associate. Roles and Responsibilities Experience with architecting, designing, and implementing AWS/Multi-cloud services Strong architecture & design experience of Deploying Enterprise applications on AWS, monitoring and performance tuning of deployed applications on AWS Expertise in developing competencies and references through proofs-of-concept Expertise in running managed services for large customers with multi cloud/vendor platforms, Infra capacity sizing, costing of AWS services to drive optimized solution architecture, leading to optimal infra investment vs performance and scale Expertise in articulating architectural choices within various AWS services and solution methodologies In-depth knowledge of AWS components like S3, EC2, VPC/Networking, Redshift, RDS, EMR, No SQL databases, DynamoDB Study existing technology landscape and understand current application workloads Understand and document technical requirements from clients, exp in building solutions & RFP's Develop AWS technical design, thought leadership, architecture blueprints and detailed documentation. Create bill of materials, including required Cloud Services (such as EC2, S3 etc.) and tools. Proven knowledge of AWS platform and tools Design, Setup and oversee the overall AWS Virtual Private Cloud VPC environment including server instance, storage instances, subnets, availability zones, network architecture including VPN connectivity between regions and subnets and HA / DR strategies etc. Define Migration strategy to move application to cloud Set up process, services and tools around cloud, execute migration plan Leverage appropriate AWS services Validate the environment to meets all security and compliance control Should have extremely good business acumen and growth mindset
A167: Cloud Monitoring Team | B167: IS1 | C167: 1-3 years | D167: =_xlfn.CONCAT(A167,"_",B167) -> Cloud Monitoring Team_IS1 | E167: Minimum of 1+ years of relevant experience in Azure or AWS cloud monitoring,responsible for monitoring & administering various Cloud platform. Good experience in working with Azure or AWS server, patching tools, troubleshooting as well as configuration. Work in collaboration with IT Management to ensure operational security, maintenance and governance being followed. Responsibilities Responsible for working in a mixed Windows and Linux Cloud & S/W environment. Minimum of 1+ years of relevant experience in enterprise level cloud Subcription/account monitoring, administration, troubleshooting issues and P1&P2 incident management. Ready to adopt new technologies and flexible to work in 24*7 shift. Must have fair technical knowledge of virtual machines IaaS (understanding Code (PaaS) and Software as a Service (SaaS). fair in Azure Iaas and PaaS technologies and services Installed, Configured, troubleshooting of Azure Compute instances, Azure Backup, Azure Site Recovery, Azure Storage Monitor, Snapshot, Azure Storage, VNet, Load Balancers and RBAC and Azure Active directory knowledge Good knowledge and experience in Azure/AWS monitoring, Log Analytics monitoring alerts and taking them to resolution. work with next level for any Implemention, deploy and configure Azure/AWS VMs, Storage, Network & Connectivity and NSGs/ASG’s good understanding of ITSM tools like ServiceNow, service management, incident, SR, CR etc. with proactivly monitoring queue and take appropriate action as needed good communication and situation/propblem handeling things
